Workbook

Sheet Cotizador
A1: Cotizador Innmobi.ai
A2: Llena solo las celdas amarillas. La hoja "Propuesta" se arma sola: imprímela o guárdala como PDF.
A4: DATOS DEL CLIENTE
A5: Contacto | B5: Nombre Apellido
A6: Inmobiliaria | B6: Inmobiliaria Ejemplo S.A. de C.V.
A7: Ciudad | B7: Ciudad de México
A8: Asesores activos | B8: 12
A9: Llamadas entrantes estimadas al mes | B9: 150
A10: Paquete de voz | B10: Ninguno
A11: Líneas simultáneas adicionales | B11: 0
A12: Paquetes de difusión WhatsApp (1,000 msj) | B12: 0
A13: Forma de pago de la mensualidad | B13: Mensual
A14: Escalón de implementación | B14: A · Lista
A15: Vendedor | B15: Nombre del vendedor
A16: Fecha de la propuesta | B16: 2026-10-08
A17: Ejemplo precargado: sobrescribe con los datos reales.
A19: RECOMENDACIÓN DE HORAS
A20: Minutos estimados al mes | B20: =$B$9*Precios!$B$11
A21: Horas estimadas al mes | B21: =$B$20/60
A22: Paquete recomendado | B22: =IF($B$21<=5,"Ninguno",IF($B$21<=10,"+5 h","+10 h")) | C22: 5 h incluidas; arriba de 15 h estimadas, platícalo con tu líder
A24: MENSUALIDAD
A25: Plan Innmobi | B25: =Precios!$B$4
A26: Paquete de voz | B26: =INDEX(Precios!$C$15:$C$17,MATCH($B$10,Precios!$A$15:$A$17,0))
A27: Líneas adicionales | B27: =$B$11*Precios!$B$8
A28: Paquetes de difusión WhatsApp | B28: =$B$12*Precios!$B$9
A29: Subtotal mensual | B29: =$B$25+$B$26+$B$27+$B$28
A30: IVA | B30: =$B$29*Precios!$B$7
A31: Total mensual con IVA | B31: =$B$29+$B$30
A32: Si paga anual: total del año sin IVA | B32: =$B$25*Precios!$B$5+($B$26+$B$27+$B$28)*12 | C32: Plan: 12 meses por el precio de 10; extras completos
A33: Si paga anual: total del año con IVA | B33: =$B$32*(1+Precios!$B$7)
A35: IMPLEMENTACIÓN
A36: Al firmar | B36: =INDEX(Precios!$B$22:$B$25,MATCH($B$14,Precios!$A$22:$A$25,0))
A37: Segundo pago | B37: =INDEX(Precios!$C$22:$C$25,MATCH($B$14,Precios!$A$22:$A$25,0))
A38: Cuándo se paga el segundo pago | B38: =INDEX(Precios!$D$22:$D$25,MATCH($B$14,Precios!$A$22:$A$25,0))
A39: Condición del escalón | B39: =INDEX(Precios!$E$22:$E$25,MATCH($B$14,Precios!$A$22:$A$25,0))
A40: Revisión (debe sumar la implementación) | B40: =IF($B$36+$B$37=Precios!$B$6,"OK","REVISAR")
A42: PAGOS
A43: Primer pago (al firmar) sin IVA | B43: =$B$36+IF($B$13="Anual",$B$32,$B$29)
A44: Primer pago con IVA | B44: =$B$43*(1+Precios!$B$7)
A45: Total primer año sin IVA | B45: =Precios!$B$6+IF($B$13="Anual",$B$32,$B$29*12)
...

Sheet Propuesta
B2: Innmobi.ai
B3: PROPUESTA COMERCIAL
B5: ="Para: "&Cotizador!$B$5&" · "&Cotizador!$B$6
B6: =Cotizador!$B$7&" · "&Cotizador!$B$8&" asesores · Fecha: "&Cotizador!$B$16&" · Vigencia: "&Precios!$B$12&" días"
B8: Lo que incluye tu plan
B9: ✓ Usuarios ilimitados: el administrador agrega y quita a su equipo
B10: ✓ Agente de voz IA 24/7 con 5 horas de llamadas al mes
B11: ✓ Número local y 2 llamadas simultáneas
B12: ✓ Servidor dedicado con respaldos diarios fuera de sitio
B13: ✓ Pipeline, Lead 360°, WhatsApp Business, Mercado Libre y Google Calendar
B14: ✓ Analytics, roles y permisos, 6 verticales configurables
B15: ✓ WhatsApp con los cargos de Meta incluidos y 500 mensajes de difusión al mes
B16: ✓ Soporte directo vía WhatsApp con el equipo que construye el producto
B18: Inversión mensual | C18: MXN sin IVA | D18: MXN con IVA
B19: Plan Innmobi | C19: =Cotizador!$B$25 | D19: =Cotizador!$B$25*(1+Precios!$B$7)
B20: ="Paquete de voz: "&Cotizador!$B$10 | C20: =Cotizador!$B$26 | D20: =Cotizador!$B$26*(1+Precios!$B$7)
B21: ="Líneas adicionales: "&Cotizador!$B$11 | C21: =Cotizador!$B$27 | D21: =Cotizador!$B$27*(1+Precios!$B$7)
B22: ="Difusión WhatsApp extra: "&Cotizador!$B$12&" x 1,000 mensajes" | C22: =Cotizador!$B$28 | D22: =Cotizador!$B$28*(1+Precios!$B$7)
B23: Total mensual | C23: =Cotizador!$B$29 | D23: =Cotizador!$B$29*(1+Precios!$B$7)
B24: =IF(Cotizador!$B$13="Anual","Pago anual elegido: "&TEXT(Cotizador!$B$32,"$#,##0")&" + IVA por 12 meses (12 por el precio de 10 en el plan)","Opción anual: 12 meses por el precio de 10 en el plan")
B26: Implementación (pago único)
B27: Implementación: migración, canales y onboarding 4 semanas | C27: =Precios!$B$6 | D27: =Precios!$B$6*(1+Precios!$B$7)
B28: Al firmar | C28: =Cotizador!$B$36 | D28: =Cotizador!$B$36*(1+Precios!$B$7)
B29: =IF(Cotizador!$B$37=0,"Sin segundo pago","Segundo pago: "&Cotizador!$B$38) | C29: =Cotizador!$B$37 | D29: =Cotizador!$B$37*(1+Precios!$B$7)
B31: Resumen de pagos
B32: Primer pago (al firmar) | C32: =Cotizador!$B$43 | D32: =Cotizador!$B$43*(1+Precios!$B$7)
B33: Total del primer año | C33: =Cotizador!$B$45 | D33: =Cotizador!$B$45*(1+Precios!$B$7)
B35: Condiciones
B36: · Precios en pesos mexicanos más IVA. Facturamos con CFDI desde OrzaTech S.A.P.I. de C.V.
B37: · La implementación arranca con el pago de firma. Duración: 4 semanas.
B38: · Horas de llamadas no usadas no se acumulan. Minuto adicional sin paquete: $6 MXN + IVA.
B39: · Los cargos de Meta por WhatsApp están incluidos (conversaciones, recordatorios y 500 mensajes de difusión al mes).
B40: · Sin lock-in: si te vas, exportamos tu data en CSV/JSON y la borramos de nuestros servidores en 30 días.
B41: =IF(Cotizador!$B$37=0,"","· Condición del calendario de pago elegido: "&Cotizador!$B$39&".")
B43: ="Tu contacto: "&Cotizador!$B$15&" · ventas@innmobi.ai · WhatsApp +52 56 2059 5320"

Sheet Precios
A1: Lista de precios Innmobi.ai (MXN, sin IVA) · no editar sin autorización
A3: Concepto | B3: Precio | C3: Nota
A4: Plan Innmobi (mensual) | B4: 4000 | C4: Usuarios ilimitados, 5 h de llamadas IA, 2 líneas, número local, servidor dedicado, todas las funciones
A5: Meses que se pagan en plan anual | B5: 10 | C5: Anual = 12 meses por el precio de 10 (aplica solo al plan, no a extras)
A6: Implementación | B6: 20000 | C6: Pago único. El monto no se negocia; solo el calendario (escalones)
A7: IVA | B7: 0.16
A8: Línea simultánea adicional (mensual) | B8: 500
A9: Paquete de 1,000 mensajes de difusión WhatsApp | B9: 1200 | C9: Incluidos 500 al mes; este paquete agrega 1,000
A10: Minuto de voz sin paquete | B10: 6 | C10: Se cobra al cierre de mes si se pasan de sus horas
A11: Minutos por llamada de calificación (promedio) | B11: 2.5 | C11: Para estimar horas
A12: Vigencia de la propuesta (días) | B12: 14
A13: Paquetes de voz
A14: Paquete | B14: Horas extra | C14: Precio mensual
A15: Ninguno | B15: 0 | C15: 0
A16: +5 h | B16: 5 | C16: 1500
A17: +10 h | B17: 10 | C17: 2700
A20: Escalones de implementación (ver sales/playbook.md)
A21: Escalón | B21: Al firmar | C21: Segundo pago | D21: Cuándo | E21: Condición
A22: A · Lista | B22: 20000 | C22: 0 | D22: — | E22: Ninguna
A23: B | B23: 15000 | C23: 5000 | D23: Al arranque de operación (semana 4) | E23: Kickoff en las próximas 2 semanas
A24: C | B24: 10000 | C24: 10000 | D24: Al arranque de operación (semana 4) | E24: Firma esta semana
A25: D · Piso | B25: 10000 | C25: 10000 | D25: A 90 días de la firma | E25: Contrato 12 meses + cargo domiciliado + caso de éxito o referido
